<?xml version='1.0'?>
<robot name="vast01_robot">

  <!-- Base Link -->
  <link name="base_link">
    <visual>
      <origin xyz="0 0 0" rpy="0 0 0" />
      <geometry>
        <box size="1 1 0.15"/>
        <!--long,wide,tall-->
      </geometry>
      <material name="blue">
        <color rgba="0 0.5 1 1"/>
      </material>
    </visual>
    <!-- Base collision -->
    <collision>
      <origin xyz="0 0 0" rpy="0 0 0" />
      <geometry>
        <box size="1 1 0.15"/>
      </geometry>
    </collision>
    <inertial>
      <mass value="5"/>
      <inertia ixx="0.13" ixy="0.0" ixz="0.0"
               iyy="0.21" iyz="0.0" izz="0.13"/>
    </inertial>
    <!-- Caster -->
    <visual name="caster">
      <origin xyz="0.2 0 -0.125" rpy="0 0 0" />
      <geometry>
         <sphere radius="0.05" />
      </geometry>
    </visual>
    <!-- Caster collision -->
    <collision>
      <origin xyz="0.2 0 -0.125" rpy="0 0 0" />
      <geometry>
        <sphere radius="0.05" />
      </geometry>
    </collision>
    <inertial>
      <mass value="0.5"/>
      <inertia ixx="0.0001" ixy="0.0" ixz="0.0"
               iyy="0.0001" iyz="0.0" izz="0.0001"/>
    </inertial>
  </link>


  <!-- left_bottom Wheel -->
  <link name="left_bottom_wheel">
    <visual>
      <origin xyz="0 0 0" rpy="1.570795 0 0.7853975" />
      <geometry>
        <cylinder length="0.1" radius="0.2" />
      </geometry>
      <material name="black">
        <color rgba="0.05 0.05 0.05 1"/>
      </material>
    </visual>
    <!-- left bottom wheel collision -->
    <collision>
      <origin xyz="0 0 0" rpy="1.570795 0 0.7853975" />
      <geometry>
        <cylinder length="0.1" radius="0.2" />
      </geometry>
    </collision>
    <inertial>
      <mass value="0.5"/>
      <inertia ixx="0.0001" ixy="0.0" ixz="0.0"
               iyy="0.0001" iyz="0.0" izz="0.0001"/>
    </inertial>
  </link>

  <joint name="joint_left_bottom_wheel" type="continuous">
    <parent link="base_link"/>
    <child link="left_bottom_wheel"/>
    <origin xyz="0.5 -0.5 0" rpy="0 0 0" />
    <axis xyz="0 1 0" />
  </joint>
  <!-- right bottom Wheel -->
  <link name="right_bottom_wheel">
    <visual>
      <origin xyz="0 0 0" rpy="1.570795 0 2.3561925" />
      <geometry>
        <cylinder length="0.1" radius="0.2" />
      </geometry>
      <material name="black"/>
    </visual>
    <!-- right bottom wheel collision -->
    <collision>
      <origin xyz="0 0 0" rpy="1.570795 0 2.3561925" />
      <geometry>
        <cylinder length="0.1" radius="0.2" />
      </geometry>
    </collision>
    <inertial>
      <mass value="0.5"/>
      <inertia ixx="0.0001" ixy="0.0" ixz="0.0"
               iyy="0.0001" iyz="0.0" izz="0.0001"/>
    </inertial>
  </link>

  <joint name="joint_right_bottom_wheel" type="continuous">
    <parent link="base_link"/>
    <child link="right_bottom_wheel"/>
    <origin xyz="0.5 0.5 0" rpy="0 0 0" />
    <axis xyz="0 1 0" />
  </joint>

<!-- left_top Wheel -->
  <link name="left_top_wheel">
    <visual>
      <origin xyz="0 0 0" rpy="1.570795 0 2.3561925" />
      <geometry>
        <cylinder length="0.1" radius="0.2" />
      </geometry>
      <material name="black"/> 
    </visual>
    <!-- left top wheel collision -->
    <collision>
      <origin xyz="0 0 0" rpy="1.570795 0 2.3561925" />
      <geometry>
        <cylinder length="0.1" radius="0.2" />
      </geometry>
    </collision>
    <inertial>
      <mass value="0.5"/>
      <inertia ixx="0.0001" ixy="0.0" ixz="0.0"
               iyy="0.0001" iyz="0.0" izz="0.0001"/>
    </inertial>
  </link>

  <joint name="joint_left_top_wheel" type="continuous">
    <parent link="base_link"/>
    <child link="left_top_wheel"/>
    <origin xyz="-0.5 -0.5 0" rpy="0 0 0" />
    <axis xyz="0 1 0" />
  </joint>
  <!-- right top Wheel -->
  <link name="right_top_wheel">
    <visual>
      <origin xyz="0 0 0" rpy="1.570795 0 0.7853975" />
      <geometry>
        <cylinder length="0.1" radius="0.2" />
      </geometry>
      <material name="black"/>
    </visual>
    <!-- right top wheel collision -->
    <collision>
      <origin xyz="0 0 0" rpy="1.570795 0 0.7853975" />
      <geometry>
        <cylinder length="0.1" radius="0.2" />
      </geometry>
    </collision>
    <inertial>
      <mass value="0.5"/>
      <inertia ixx="0.0001" ixy="0.0" ixz="0.0"
               iyy="0.0001" iyz="0.0" izz="0.0001"/>
    </inertial>
  </link>

  <joint name="joint_right_top_wheel" type="continuous">
    <parent link="base_link"/>
    <child link="right_top_wheel"/>
    <origin xyz="-0.5 0.5 0" rpy="0 0 0" />
    <axis xyz="0 1 0" />
  </joint>

  <!-- left_bottom cylinder -->
  <link name="left_bottom_cylinder">
    <visual>
      <origin xyz="0 0 0" rpy="0 0 0" />
      <geometry>
        <box size="0.03 0.03 1.5" />
      </geometry>
      <material name="white">
        <color rgba="0 0 0 1"/>
      </material>
    </visual>
    <!-- left bottom cylinder collision -->
    <collision>
      <origin xyz="0 0 0" rpy="0 0 0" />
      <geometry>
        <box size="0.03 0.03 1.5"/>
      </geometry>
    </collision>
    <inertial>
      <mass value="0.5"/>
      <inertia ixx="0.0001" ixy="0.0" ixz="0.0"
               iyy="0.0001" iyz="0.0" izz="0.0001"/>
    </inertial>
  </link>

  <joint name="joint_left_bottom_cylinder" type="fixed">
    <parent link="base_link"/>
    <child link="left_bottom_cylinder"/>
    <origin xyz="0.25 -0.40 0.7" rpy="0 0 0" />
    <axis xyz="0 1 0" />
  </joint>
<!-- right_bottom cylinder -->
  <link name="right_bottom_cylinder">
    <visual>
      <origin xyz="0 0 0" rpy="0 0 0" />
      <geometry>
        <box size="0.03 0.03 1.5" />
      </geometry>
      <material name="white"/> 
    </visual>
    <!-- right bottom cylinder collision -->
    <collision>
      <origin xyz="0 0 0" rpy="0 0 0" />
      <geometry>
        <box size="0.03 0.03 1.5"/>
      </geometry>
    </collision>
    <inertial>
      <mass value="0.5"/>
      <inertia ixx="0.0001" ixy="0.0" ixz="0.0"
               iyy="0.0001" iyz="0.0" izz="0.0001"/>
    </inertial>
  </link>

  <joint name="joint_right_bottom_cylinder" type="fixed">
    <parent link="base_link"/>
    <child link="right_bottom_cylinder"/>
    <origin xyz="0.25 0.40 0.7" rpy="0 0 0" />
    <axis xyz="0 1 0" />
  </joint>
<!-- between_top_cylinder -->
  <link name="between_top_cylinder">
    <visual>
      <origin xyz="0 0 0" rpy="0 0 0" />
      <geometry>
        <box size="0.03 0.03 1.5" />
      </geometry>
      <material name="white"/>
    </visual>
    <!-- between bottom cylinder collision -->
    <collision>
      <origin xyz="0 0 0" rpy="0 0 0" />
      <geometry>
        <box size="0.03 0.03 1.5"/>
      </geometry>
    </collision>
    <inertial>
      <mass value="0.5"/>
      <inertia ixx="0.0001" ixy="0.0" ixz="0.0"
               iyy="0.0001" iyz="0.0" izz="0.0001"/>
    </inertial>
  </link>

  <joint name="joint_between_top_cylinder" type="fixed">
    <parent link="base_link"/>
    <child link="between_top_cylinder"/>
    <origin xyz="-0.4 0 0.7" rpy="0 0 0" />
    <axis xyz="0 1 0" />
  </joint>
<!-- hold_box1 -->
  <link name="hold_box1">
    <visual>
      <origin xyz="0 0 0" rpy="0 0 0" />
      <geometry>
        <box size="0.8 0.8 0.01" />
      </geometry>
      <material name="blue"/>
    </visual>
    <!-- hold box1 collision -->
    <collision>
      <origin xyz="0 0 0" rpy="0 0 0" />
      <geometry>
        <box size="0.8 0.8 0.01"/>
      </geometry>
    </collision>
    <inertial>
      <mass value="0.5"/>
      <inertia ixx="0.0001" ixy="0.0" ixz="0.0"
               iyy="0.0001" iyz="0.0" izz="0.0001"/>
    </inertial>
  </link>

  <joint name="joint_hold_box1" type="fixed">
    <parent link="base_link"/>
    <child link="hold_box1"/>
    <origin xyz="0 0 0.75" rpy="0 0 0" />
    <axis xyz="0 0 0" />
  </joint>
<!-- hold_box2 -->
  <link name="hold_box2">
    <visual>
      <origin xyz="0 0 0" rpy="0 0 0" />
      <geometry>
        <box size="0.8 0.8 0.01" />
      </geometry>
      <material name="blue"/>
    </visual>
    <!-- hold box2 collision -->
    <collision>
      <origin xyz="0 0 0" rpy="0 0 0" />
      <geometry>
        <box size="0.8 0.8 0.01"/>
      </geometry>
    </collision>
    <inertial>
      <mass value="0.5"/>
      <inertia ixx="0.0001" ixy="0.0" ixz="0.0"
               iyy="0.0001" iyz="0.0" izz="0.0001"/>
    </inertial>
  </link>

  <joint name="joint_hold_box2" type="fixed">
    <parent link="base_link"/>
    <child link="hold_box2"/>
    <origin xyz="0 0 1.43" rpy="0 0 0" />
    <axis xyz="0 0 0" />
  </joint>
</robot>
